2025-07-03 10:04:15,656-INFO-fact_sales table started loading .. ...
2025-07-03 10:04:15,821-INFO-fact_sales table completed loading .. ...
2025-07-03 10:07:29,655-INFO-fact_sales table started loading .. ...
2025-07-03 10:07:29,666-ERROR-Error encounted while loading fact sales data,(pymysql.err.IntegrityError) (1062, "Duplicate entry '48' for key 'fact_sales.PRIMARY'")
[SQL: insert into fact_sales( sales_id , product_id, store_id,quantity,total_amount,sale_date)
                    select sales_id , product_id, store_id,quantity,total_amount,sale_date from joiner_sales_products_stores_data]
(Background on this error at: https://sqlalche.me/e/20/gkpj)
Traceback (most recent call last):
  File "C:\Python313\Lib\site-packages\sqlalchemy\engine\base.py", line 1963, in _exec_single_context
    self.dialect.do_execute(
    ~~~~~~~~~~~~~~~~~~~~~~~^
        cursor, str_statement, effective_parameters, context
        ^^^^^^^^^^^^^^^^^^^^^^^^^^^^^^^^^^^^^^^^^^^^^^^^^^^^
    )
    ^
  File "C:\Python313\Lib\site-packages\sqlalchemy\engine\default.py", line 943, in do_execute
    cursor.execute(statement, parameters)
    ~~~~~~~~~~~~~~^^^^^^^^^^^^^^^^^^^^^^^
  File "C:\Python313\Lib\site-packages\pymysql\cursors.py", line 153, in execute
    result = self._query(query)
  File "C:\Python313\Lib\site-packages\pymysql\cursors.py", line 322, in _query
    conn.query(q)
    ~~~~~~~~~~^^^
  File "C:\Python313\Lib\site-packages\pymysql\connections.py", line 563, in query
    self._affected_rows = self._read_query_result(unbuffered=unbuffered)
                          ~~~~~~~~~~~~~~~~~~~~~~~^^^^^^^^^^^^^^^^^^^^^^^
  File "C:\Python313\Lib\site-packages\pymysql\connections.py", line 825, in _read_query_result
    result.read()
    ~~~~~~~~~~~^^
  File "C:\Python313\Lib\site-packages\pymysql\connections.py", line 1199, in read
    first_packet = self.connection._read_packet()
  File "C:\Python313\Lib\site-packages\pymysql\connections.py", line 775, in _read_packet
    packet.raise_for_error()
    ~~~~~~~~~~~~~~~~~~~~~~^^
  File "C:\Python313\Lib\site-packages\pymysql\protocol.py", line 219, in raise_for_error
    err.raise_mysql_exception(self._data)
    ~~~~~~~~~~~~~~~~~~~~~~~~~^^^^^^^^^^^^
  File "C:\Python313\Lib\site-packages\pymysql\err.py", line 150, in raise_mysql_exception
    raise errorclass(errno, errval)
pymysql.err.IntegrityError: (1062, "Duplicate entry '48' for key 'fact_sales.PRIMARY'")

The above exception was the direct cause of the following exception:

Traceback (most recent call last):
  File "C:\Users\abc\PycharmProjects\PythonProject1\practice_repo_testing\CodeBase\load_local.py", line 26, in load_fact_sales_table
    conn.execute(query)
    ~~~~~~~~~~~~^^^^^^^
  File "C:\Python313\Lib\site-packages\sqlalchemy\engine\base.py", line 1415, in execute
    return meth(
        self,
        distilled_parameters,
        execution_options or NO_OPTIONS,
    )
  File "C:\Python313\Lib\site-packages\sqlalchemy\sql\elements.py", line 523, in _execute_on_connection
    return connection._execute_clauseelement(
           ~~~~~~~~~~~~~~~~~~~~~~~~~~~~~~~~~^
        self, distilled_params, execution_options
        ^^^^^^^^^^^^^^^^^^^^^^^^^^^^^^^^^^^^^^^^^
    )
    ^
  File "C:\Python313\Lib\site-packages\sqlalchemy\engine\base.py", line 1637, in _execute_clauseelement
    ret = self._execute_context(
        dialect,
    ...<8 lines>...
        cache_hit=cache_hit,
    )
  File "C:\Python313\Lib\site-packages\sqlalchemy\engine\base.py", line 1842, in _execute_context
    return self._exec_single_context(
           ~~~~~~~~~~~~~~~~~~~~~~~~~^
        dialect, context, statement, parameters
        ^^^^^^^^^^^^^^^^^^^^^^^^^^^^^^^^^^^^^^^
    )
    ^
  File "C:\Python313\Lib\site-packages\sqlalchemy\engine\base.py", line 1982, in _exec_single_context
    self._handle_dbapi_exception(
    ~~~~~~~~~~~~~~~~~~~~~~~~~~~~^
        e, str_statement, effective_parameters, cursor, context
        ^^^^^^^^^^^^^^^^^^^^^^^^^^^^^^^^^^^^^^^^^^^^^^^^^^^^^^^
    )
    ^
  File "C:\Python313\Lib\site-packages\sqlalchemy\engine\base.py", line 2351, in _handle_dbapi_exception
    raise sqlalchemy_exception.with_traceback(exc_info[2]) from e
  File "C:\Python313\Lib\site-packages\sqlalchemy\engine\base.py", line 1963, in _exec_single_context
    self.dialect.do_execute(
    ~~~~~~~~~~~~~~~~~~~~~~~^
        cursor, str_statement, effective_parameters, context
        ^^^^^^^^^^^^^^^^^^^^^^^^^^^^^^^^^^^^^^^^^^^^^^^^^^^^
    )
    ^
  File "C:\Python313\Lib\site-packages\sqlalchemy\engine\default.py", line 943, in do_execute
    cursor.execute(statement, parameters)
    ~~~~~~~~~~~~~~^^^^^^^^^^^^^^^^^^^^^^^
  File "C:\Python313\Lib\site-packages\pymysql\cursors.py", line 153, in execute
    result = self._query(query)
  File "C:\Python313\Lib\site-packages\pymysql\cursors.py", line 322, in _query
    conn.query(q)
    ~~~~~~~~~~^^^
  File "C:\Python313\Lib\site-packages\pymysql\connections.py", line 563, in query
    self._affected_rows = self._read_query_result(unbuffered=unbuffered)
                          ~~~~~~~~~~~~~~~~~~~~~~~^^^^^^^^^^^^^^^^^^^^^^^
  File "C:\Python313\Lib\site-packages\pymysql\connections.py", line 825, in _read_query_result
    result.read()
    ~~~~~~~~~~~^^
  File "C:\Python313\Lib\site-packages\pymysql\connections.py", line 1199, in read
    first_packet = self.connection._read_packet()
  File "C:\Python313\Lib\site-packages\pymysql\connections.py", line 775, in _read_packet
    packet.raise_for_error()
    ~~~~~~~~~~~~~~~~~~~~~~^^
  File "C:\Python313\Lib\site-packages\pymysql\protocol.py", line 219, in raise_for_error
    err.raise_mysql_exception(self._data)
    ~~~~~~~~~~~~~~~~~~~~~~~~~^^^^^^^^^^^^
  File "C:\Python313\Lib\site-packages\pymysql\err.py", line 150, in raise_mysql_exception
    raise errorclass(errno, errval)
sqlalchemy.exc.IntegrityError: (pymysql.err.IntegrityError) (1062, "Duplicate entry '48' for key 'fact_sales.PRIMARY'")
[SQL: insert into fact_sales( sales_id , product_id, store_id,quantity,total_amount,sale_date)
                    select sales_id , product_id, store_id,quantity,total_amount,sale_date from joiner_sales_products_stores_data]
(Background on this error at: https://sqlalche.me/e/20/gkpj)
2025-07-03 10:07:30,033-INFO-fact_inventory table started loading .. ...
2025-07-03 10:07:30,062-INFO-fact_inventory table completed loading .. ...
2025-07-03 10:10:36,902-INFO-fact_sales table started loading .. ...
2025-07-03 10:10:36,972-ERROR-Error encounted while loading fact sales data,(pymysql.err.IntegrityError) (1062, "Duplicate entry '48' for key 'fact_sales.PRIMARY'")
[SQL: insert into fact_sales( sales_id , product_id, store_id,quantity,total_amount,sale_date)
                    select sales_id , product_id, store_id,quantity,total_amount,sale_date from joiner_sales_products_stores_data]
(Background on this error at: https://sqlalche.me/e/20/gkpj)
Traceback (most recent call last):
  File "C:\Python313\Lib\site-packages\sqlalchemy\engine\base.py", line 1963, in _exec_single_context
    self.dialect.do_execute(
    ~~~~~~~~~~~~~~~~~~~~~~~^
        cursor, str_statement, effective_parameters, context
        ^^^^^^^^^^^^^^^^^^^^^^^^^^^^^^^^^^^^^^^^^^^^^^^^^^^^
    )
    ^
  File "C:\Python313\Lib\site-packages\sqlalchemy\engine\default.py", line 943, in do_execute
    cursor.execute(statement, parameters)
    ~~~~~~~~~~~~~~^^^^^^^^^^^^^^^^^^^^^^^
  File "C:\Python313\Lib\site-packages\pymysql\cursors.py", line 153, in execute
    result = self._query(query)
  File "C:\Python313\Lib\site-packages\pymysql\cursors.py", line 322, in _query
    conn.query(q)
    ~~~~~~~~~~^^^
  File "C:\Python313\Lib\site-packages\pymysql\connections.py", line 563, in query
    self._affected_rows = self._read_query_result(unbuffered=unbuffered)
                          ~~~~~~~~~~~~~~~~~~~~~~~^^^^^^^^^^^^^^^^^^^^^^^
  File "C:\Python313\Lib\site-packages\pymysql\connections.py", line 825, in _read_query_result
    result.read()
    ~~~~~~~~~~~^^
  File "C:\Python313\Lib\site-packages\pymysql\connections.py", line 1199, in read
    first_packet = self.connection._read_packet()
  File "C:\Python313\Lib\site-packages\pymysql\connections.py", line 775, in _read_packet
    packet.raise_for_error()
    ~~~~~~~~~~~~~~~~~~~~~~^^
  File "C:\Python313\Lib\site-packages\pymysql\protocol.py", line 219, in raise_for_error
    err.raise_mysql_exception(self._data)
    ~~~~~~~~~~~~~~~~~~~~~~~~~^^^^^^^^^^^^
  File "C:\Python313\Lib\site-packages\pymysql\err.py", line 150, in raise_mysql_exception
    raise errorclass(errno, errval)
pymysql.err.IntegrityError: (1062, "Duplicate entry '48' for key 'fact_sales.PRIMARY'")

The above exception was the direct cause of the following exception:

Traceback (most recent call last):
  File "C:\Users\abc\PycharmProjects\PythonProject1\practice_repo_testing\CodeBase\load_local.py", line 26, in load_fact_sales_table
    conn.execute(query)
    ~~~~~~~~~~~~^^^^^^^
  File "C:\Python313\Lib\site-packages\sqlalchemy\engine\base.py", line 1415, in execute
    return meth(
        self,
        distilled_parameters,
        execution_options or NO_OPTIONS,
    )
  File "C:\Python313\Lib\site-packages\sqlalchemy\sql\elements.py", line 523, in _execute_on_connection
    return connection._execute_clauseelement(
           ~~~~~~~~~~~~~~~~~~~~~~~~~~~~~~~~~^
        self, distilled_params, execution_options
        ^^^^^^^^^^^^^^^^^^^^^^^^^^^^^^^^^^^^^^^^^
    )
    ^
  File "C:\Python313\Lib\site-packages\sqlalchemy\engine\base.py", line 1637, in _execute_clauseelement
    ret = self._execute_context(
        dialect,
    ...<8 lines>...
        cache_hit=cache_hit,
    )
  File "C:\Python313\Lib\site-packages\sqlalchemy\engine\base.py", line 1842, in _execute_context
    return self._exec_single_context(
           ~~~~~~~~~~~~~~~~~~~~~~~~~^
        dialect, context, statement, parameters
        ^^^^^^^^^^^^^^^^^^^^^^^^^^^^^^^^^^^^^^^
    )
    ^
  File "C:\Python313\Lib\site-packages\sqlalchemy\engine\base.py", line 1982, in _exec_single_context
    self._handle_dbapi_exception(
    ~~~~~~~~~~~~~~~~~~~~~~~~~~~~^
        e, str_statement, effective_parameters, cursor, context
        ^^^^^^^^^^^^^^^^^^^^^^^^^^^^^^^^^^^^^^^^^^^^^^^^^^^^^^^
    )
    ^
  File "C:\Python313\Lib\site-packages\sqlalchemy\engine\base.py", line 2351, in _handle_dbapi_exception
    raise sqlalchemy_exception.with_traceback(exc_info[2]) from e
  File "C:\Python313\Lib\site-packages\sqlalchemy\engine\base.py", line 1963, in _exec_single_context
    self.dialect.do_execute(
    ~~~~~~~~~~~~~~~~~~~~~~~^
        cursor, str_statement, effective_parameters, context
        ^^^^^^^^^^^^^^^^^^^^^^^^^^^^^^^^^^^^^^^^^^^^^^^^^^^^
    )
    ^
  File "C:\Python313\Lib\site-packages\sqlalchemy\engine\default.py", line 943, in do_execute
    cursor.execute(statement, parameters)
    ~~~~~~~~~~~~~~^^^^^^^^^^^^^^^^^^^^^^^
  File "C:\Python313\Lib\site-packages\pymysql\cursors.py", line 153, in execute
    result = self._query(query)
  File "C:\Python313\Lib\site-packages\pymysql\cursors.py", line 322, in _query
    conn.query(q)
    ~~~~~~~~~~^^^
  File "C:\Python313\Lib\site-packages\pymysql\connections.py", line 563, in query
    self._affected_rows = self._read_query_result(unbuffered=unbuffered)
                          ~~~~~~~~~~~~~~~~~~~~~~~^^^^^^^^^^^^^^^^^^^^^^^
  File "C:\Python313\Lib\site-packages\pymysql\connections.py", line 825, in _read_query_result
    result.read()
    ~~~~~~~~~~~^^
  File "C:\Python313\Lib\site-packages\pymysql\connections.py", line 1199, in read
    first_packet = self.connection._read_packet()
  File "C:\Python313\Lib\site-packages\pymysql\connections.py", line 775, in _read_packet
    packet.raise_for_error()
    ~~~~~~~~~~~~~~~~~~~~~~^^
  File "C:\Python313\Lib\site-packages\pymysql\protocol.py", line 219, in raise_for_error
    err.raise_mysql_exception(self._data)
    ~~~~~~~~~~~~~~~~~~~~~~~~~^^^^^^^^^^^^
  File "C:\Python313\Lib\site-packages\pymysql\err.py", line 150, in raise_mysql_exception
    raise errorclass(errno, errval)
sqlalchemy.exc.IntegrityError: (pymysql.err.IntegrityError) (1062, "Duplicate entry '48' for key 'fact_sales.PRIMARY'")
[SQL: insert into fact_sales( sales_id , product_id, store_id,quantity,total_amount,sale_date)
                    select sales_id , product_id, store_id,quantity,total_amount,sale_date from joiner_sales_products_stores_data]
(Background on this error at: https://sqlalche.me/e/20/gkpj)
2025-07-03 10:10:36,998-INFO-fact_inventory table started loading .. ...
2025-07-03 10:10:36,999-ERROR-Error encounted while loading fact inventory data,Connection.execute() got an unexpected keyword argument 'if_exists'
Traceback (most recent call last):
  File "C:\Users\abc\PycharmProjects\PythonProject1\practice_repo_testing\CodeBase\load_local.py", line 42, in load_fact_inventory_table
    conn.execute(query, mysql_engine_tgt, if_exists='replace', index=False)
    ~~~~~~~~~~~~^^^^^^^^^^^^^^^^^^^^^^^^^^^^^^^^^^^^^^^^^^^^^^^^^^^^^^^^^^^
TypeError: Connection.execute() got an unexpected keyword argument 'if_exists'
2025-07-03 10:11:58,441-INFO-fact_sales table started loading .. ...
2025-07-03 10:11:58,479-INFO-fact_sales table completed loading .. ...
2025-07-03 10:11:58,481-INFO-fact_inventory table started loading .. ...
2025-07-03 10:11:58,503-INFO-fact_inventory table completed loading .. ...
